<?xml version="1.0" ?>
<robot name="AKB_Object">
	
	
	<link name="link1">
		
		
		<visual>
			
			
			<origin rpy="0.0 0.0 0.0" xyz="0.0 0.0 0.0"/>
			
			
			<geometry>
				
				
				<mesh filename="./part_meshes/link1.obj" scale="1 1 1"/>
				
			
			</geometry>
			
		
		</visual>
		
		
		<inertial>
			
			
			<origin rpy="0 0 0" xyz="0 0 0"/>
			
			
			<mass value="1.0"/>
			
			
			<inertia ixx="0.0" ixy="0.0" ixz="0.0" iyy="0.0" iyz="0.0" izz="0.0"/>
			
		
		</inertial>
		
	
	</link>
	
	
	<link name="link2">
		
		
		<visual>
			
			
			<origin rpy="0.0 0.0 0.0" xyz="-0.003095 0.000464 -0.000332"/>
			
			
			<geometry>
				
				
				<mesh filename="./part_meshes/link2.obj" scale="1 1 1"/>
				
			
			</geometry>
			
		
		</visual>
		
		
		<inertial>
			
			
			<origin rpy="0 0 0" xyz="0 0 0"/>
			
			
			<mass value="1.0"/>
			
			
			<inertia ixx="0.0" ixy="0.0" ixz="0.0" iyy="0.0" iyz="0.0" izz="0.0"/>
			
		
		</inertial>
		
	
	</link>
	
	
	<joint name="link1|revolute|link2" type="revolute">
		
		
		<parent link="link1"/>
		
		
		<child link="link2"/>
		
		
		<origin rpy="0 0 0" xyz="0.003095 -0.000464 0.000332"/>
		
		
		<axis xyz="1.0 0.0 0.0"/>
		
		
		<limit effort="1.0" lower="-0.001" upper="1.4" velocity="1000"/>
		
	
	</joint>
	

</robot>
